<mujoco model="tailDoedicurus">
  <option timestep="0.008" iterations="50" solver="Newton" tolerance="1e-10" collision="predefined">
    <flag energy="enable"/>
  </option>
  <visual>
    <rgba haze="1 1 1 1"/>
  </visual>

  <default>
    <joint type="hinge" pos="0 0 0" axis="0 0 1" limited="true" range="-12.5 12.5" damping="0.2" solimplimit = "0.95 1 0.001 1 3"/>
    <geom material="bodies" />
  </default>

  <asset>
    <texture type="skybox" builtin="gradient" rgb1="1 1 1" rgb2="1 1 1" width="512" height="512"/>

    <texture name="texplane" type="2d" builtin="checker" rgb1=".25 .25 .25" rgb2=".3 .3 .3" width="512" height="512" mark="cross" markrgb=".8 .8 .8"/>

    <material name="matplane" reflectance="0.3" texture="texplane" texrepeat="2 2" texuniform="true"/>

    <material name="bodies" rgba="0.482353 0.52549 0.301961 1" reflectance="0" shininess="0.5"/>

    <mesh file="..\..\..\Obj\Club doedicurus_final_version_full_size.obj" name="clubMesh" scale="0.001 0.001 0.001"/>

    <mesh file="..\..\..\Obj\Carapace v9.obj" name="carapace" />
  </asset>

  <worldbody>
    <!--<geom name="floor" pos="0 0 -0.5" size="0 0 1" type="plane" material="matplane"/>-->
    <geom name="floor" pos="0.18 0 -0.6" size="2.2 0.1" type="cylinder" material="matplane"/>
    <camera name="closeup" pos="0.1 -0.4 .3" xyaxes="1 0 0 0 1 1"/>
    <light directional="true" diffuse="1 1 1" specular=".5 .5 .5" pos="0 1 7" dir="0 -0.5 -1"/>
    <body pos = "1 1 0">
      <geom name ="box" type ="box" size = "0.15 0.15 0.15" pos ="0.8 -0.5 -0.35" rgba ="1 0 0 1"/>
    </body>
    <body pos="0 0 0">
      <joint name="J0" range="-90 90"/>
      <geom name="body" type = "mesh" mesh="carapace" pos="0.4 -0.03 -0.02" euler="0 0 90" mass = "1250"/>
      <site name="gyro" pos="0 0 0" size="0.01" />
      <site name="start1" pos="0 0.2 0" size="0.01"/>
      <site name="start2" pos="0 -0.2 0" size="0.01"/>
      <body pos="0.4 0 0">
        <geom name="C1" type="cylinder" pos="0.055 0 0" size=".3234 0.055" euler="0 90 0" mass="49.63"/>
        <site name="sl1" pos="0.0550 0.1617 0" size="0.01"/>
        <site name="sr1" pos="0.0550 -0.1617 0" size="0.01"/>
        <joint name="J1" />
        <geom name="J1" type="cylinder" pos="0 0 0" size=".003 .004" rgba=".5 .1 .8 .5"  group="1"/>   

        <body pos="0.11 0 0">
          <geom name="C2" type="cylinder" pos="0.055 0 0" size=".2695 0.055" euler="0 90 0" mass="34.46" />
          <site name="sl2" pos="0.055 0.1347 0" size="0.01"/>
          <site name="sr2" pos="0.055 -0.1347 0" size="0.01"/>
          <joint name="J2" />
          <geom name="J2" type="cylinder" pos="0 0 0" size=".003 .004" rgba=".5 .1 .8 .5" mass="0" group="1"/>

          <body pos = "0.11 0 0">
            <geom name="C3" type="cylinder" pos="0.055 0 0" size=".2246 0.055" euler="0 90 0" mass="23.93"/>
            <site name="sl3" pos="0.055 0.1123 0" size="0.01"/>
            <site name="sr3" pos="0.055 -0.1123 0" size="0.01"/>
            <joint name="J3"/>
            <geom name ="J3" type="cylinder" pos="0 0 0" size=".003 .004" rgba=".5 .1 .8 .5" mass="0" group="1"/>  

            <body pos = "0.11 0 0">
              <geom name="C4" type="cylinder" pos="0.055 0 0" size=".1871 0.055" euler="0 90 0" mass="16.62"/>
              <site name="sl4" pos="0.055 0.0935 0" size="0.01"/>
              <site name="sr4" pos="0.055 -0.0935 0" size="0.01"/>
              <joint name="J4"/>
              <geom name ="J4" type="cylinder" pos="0 0 0" size=".003 .004" rgba=".5 .1 .8 .5" mass="0" group="1"/>  

              <body pos = "0.11 0 0">
                <geom name="C5" type="cylinder" pos="0.055 0 0" size=".1560 0.055" euler="0 90 0" mass="11.54"/>
                <site name="sl5" pos="0.055 0.078 0" size="0.01"/>
                <site name="sr5" pos="0.055 -0.078 0" size="0.01"/>
                <joint name="J5"/>
                <geom name ="J5" type="cylinder" pos="0 0 0" size=".003 .004" rgba=".5 .1 .8 .5" mass="0" group="1"/>  

                <body pos = "0.11 0 0">
                  <geom name="C6" type="cylinder" pos="0.055 0 0" size=".1300 0.055" euler="0 90 0" mass="8.02"/>
                  <site name="sl6" pos="0.055 0.065 0" size="0.01"/>
                  <site name="sr6" pos="0.055 -0.065 0" size="0.01"/> 
                  <joint name="J6"/>
                  <geom name ="J6" type="cylinder" pos="0 0 0" size=".003 .004" rgba=".5 .1 .8 .5" mass="0" group="1"/>
                  
                  <body pos = "0.11 0 0">
                    <geom name="club" type = "mesh" mesh="clubMesh" pos="0.5 0 0" euler="0 0 180" mass = "43.59"/>
                    <site name="tip" pos="0.8 0 0" size="0.01"/>
                    <site name="cm" pos="0.51 0 0" size="0.01"/>
                    <joint name="J7"/>
                    <geom name ="J7" type="cylinder" pos="0 0 0" size=".003 .004" rgba=".5 .1 .8 .5" mass="0" group="1"/>
                    <site name="end1" pos="0.055 0.055 0" size="0.01"/>
                    <site name="end2" pos="0.055 -0.055 0" size="0.01"/> 
                  </body>
                </body>
              </body>
            </body>
          </body>
        </body>
      </body>
    </body>
  </worldbody>

  <tendon>
    <spatial name="tendon1" width="0.01" rgba= "0.8 1. 0.4 1.">
      <site site="start1"/>
      <site site="sl1"/>
      <site site="sl2"/>
      <site site="sl3"/>
      <site site="sl4"/>
      <site site="sl5"/>
      <site site="sl6"/>
      <site site="end1"/>
    </spatial>

    <spatial name="tendon2" width="0.01" rgba= "0.8 1. 0.4 1.">
      <site site="start2"/>
      <site site="sr1"/>
      <site site="sr2"/>
      <site site="sr3"/>
      <site site="sr4"/>
      <site site="sr5"/>
      <site site="sr6"/>
      <site site="end2"/>
    </spatial>
  </tendon>

  <sensor>
    <velocimeter name="gpstip" site="tip"/>
    <velocimeter name="gpscm" site="cm"/>
	<force name="tendonForce" site="start1"/>
  </sensor>

  <actuator>
    <muscle name="muscle1" force="71636" tendon="tendon1"/>
    <muscle name="muscle2" force="71636" tendon="tendon2" />
    <motor name="J0" gear="100000" joint="J0" />
  </actuator>
</mujoco>